Workbook

Sheet Inputs
A1: John B. Sanfilippo & Son, Inc. — assumptions
A2: Fiscal year 2026 is year 0. All figures in USD thousands. Working-capital ratios are stated against the same year's sales; net PP&E is a turnover on next year's.
A4: Assumption | B4: Year 1 | C4: Year 2 | D4: Year 3 | E4: Year 4 | F4: Year 5 | G4: Terminal
A5: Growth and margin
A6: Sales growth | B6: 0.045 | C6: 0.065 | D6: 0.06 | E6: 0.045 | F6: 0.035 | G6: 0.035
A7: EBITDA margin | B7: 0.102 | C7: 0.106 | D7: 0.108 | E7: 0.108 | F7: 0.108 | G7: 0.108
A8: Property, plant and equipment
A9: Next-year sales / net PP&E | B9: 5.25 | C9: 5.6 | D9: 5.9 | E9: 6.15 | F9: 6.3 | G9: 6.3
A10: Depreciation / prior net PP&E | B10: 0.14 | C10: 0.135 | D10: 0.13 | E10: 0.13 | F10: 0.13 | G10: 0.13
A11: Operating assets, as a share of sales
A12: Accounts receivable | B12: 0.072 | C12: 0.071 | D12: 0.071 | E12: 0.07 | F12: 0.07 | G12: 0.07
A13: Inventories | B13: 0.209 | C13: 0.205 | D13: 0.2 | E13: 0.197 | F13: 0.195 | G13: 0.195
A14: Prepaid expenses and other current assets | B14: 0.015 | C14: 0.014 | D14: 0.013 | E14: 0.012 | F14: 0.012 | G14: 0.012
A15: Operating liabilities, as a share of sales
A16: Accounts payable | B16: 0.062 | C16: 0.06 | D16: 0.058 | E16: 0.056 | F16: 0.055 | G16: 0.055
A17: Accrued payroll and related benefits | B17: 0.029 | C17: 0.028 | D17: 0.027 | E17: 0.026 | F17: 0.026 | G17: 0.026
A18: Other accrued expenses | B18: 0.018 | C18: 0.017 | D18: 0.016 | E18: 0.016 | F18: 0.016 | G18: 0.016
A19: Long-term workers' compensation liabilities | B19: 0.009 | C19: 0.009 | D19: 0.009 | E19: 0.009 | F19: 0.009 | G19: 0.009
A20: Taxes
A21: Cash tax rate on taxable income | B21: 0.27 | C21: 0.27 | D21: 0.27 | E21: 0.27 | F21: 0.27 | G21: 0.27
A23: Rates and year-0 balances
A24: WACC | B24: 0.08
A25: NOL limitation | B25: 0.8
A26: Opening NOL carryforward | B26: 0
A27: Diluted shares | B27: 11777.4
A28: Sales, year 0 | B28: 1175673
A29: Net PP&E, year 0 | B29: 243702
A30: Net working capital, year 0 | B30: 209479
A32: Claims on the enterprise
A33: Plus cash | B33: 1147
A34: Plus rental investment property | B34: 12263
A35: Less revolving credit facility | B35: 33615
A36: Less long term debt | B36: 49619
A37: Less bank overdraft | B37: 237
A38: Less unfunded pension | B38: 29193

Sheet Model
A1: Forecast — every cell below is a formula over the Inputs sheet
A3: Forecast | B3: Year 1 | C3: Year 2 | D3: Year 3 | E3: Year 4 | F3: Year 5 | G3: Year 6 · transition | H3: Year 7 · perpetuity | I3: Year 8 · for year 7's PP&E
A4: Sales | B4: =Inputs!$B$28*(1+Inputs!$B$6) | C4: =B4*(1+Inputs!$C$6) | D4: =C4*(1+Inputs!$D$6) | E4: =D4*(1+Inputs!$E$6) | F4: =E4*(1+Inputs!$F$6) | G4: =F4*(1+Inputs!$G$6) | H4: =G4*(1+Inputs!$G$6) | I4: =H4*(1+Inputs!$G$6)
A5: Next-year sales | B5: =C4 | C5: =D4 | D5: =E4 | E5: =F4 | F5: =G4 | G5: =H4 | H5: =I4
A6: EBITDA | B6: =Inputs!$B$7*B4 | C6: =Inputs!$C$7*C4 | D6: =Inputs!$D$7*D4 | E6: =Inputs!$E$7*E4 | F6: =Inputs!$F$7*F4 | G6: =Inputs!$G$7*G4 | H6: =Inputs!$G$7*H4
A7: Net PP&E, closing | B7: =B5/Inputs!$B$9 | C7: =C5/Inputs!$C$9 | D7: =D5/Inputs!$D$9 | E7: =E5/Inputs!$E$9 | F7: =F5/Inputs!$F$9 | G7: =G5/Inputs!$G$9 | H7: =H5/Inputs!$G$9
A8: Depreciation | B8: =Inputs!$B$10*Inputs!$B$29 | C8: =Inputs!$C$10*B7 | D8: =Inputs!$D$10*C7 | E8: =Inputs!$E$10*D7 | F8: =Inputs!$F$10*E7 | G8: =Inputs!$G$10*F7 | H8: =Inputs!$G$10*G7
A9: Capital expenditure | B9: =B7-Inputs!$B$29+B8 | C9: =C7-B7+C8 | D9: =D7-C7+D8 | E9: =E7-D7+E8 | F9: =F7-E7+F8 | G9: =G7-F7+G8 | H9: =H7-G7+H8
A10: Net working capital, closing | B10: =(Inputs!B$12+Inputs!B$13+Inputs!B$14-Inputs!B$16-Inputs!B$17-Inputs!B$18-Inputs!B$19)*B4 | C10: =(Inputs!C$12+Inputs!C$13+Inputs!C$14-Inputs!C$16-Inputs!C$17-Inputs!C$18-Inputs!C$19)*C4 | D10: =(Inputs!D$12+Inputs!D$13+Inputs!D$14-Inputs!D$16-Inputs!D$17-Inputs!D$18-Inputs!D$19)*D4 | E10: =(Inputs!E$12+Inputs!E$13+Inputs!E$14-Inputs!E$16-Inputs!E$17-Inputs!E$18-Inputs!E$19)*E4 | F10: =(Inputs!F$12+Inputs!F$13+Inputs!F$14-Inputs!F$16-Inputs!F$17-Inputs!F$18-Inputs!F$19)*F4 | G10: =(Inputs!G$12+Inputs!G$13+Inputs!G$14-Inputs!G$16-Inputs!G$17-Inputs!G$18-Inputs!G$19)*G4 | H10: =(Inputs!G$12+Inputs!G$13+Inputs!G$14-Inputs!G$16-Inputs!G$17-Inputs!G$18-Inputs!G$19)*H4
A11: Investment in working capital | B11: =B10-Inputs!$B$30 | C11: =C10-B10 | D11: =D10-C10 | E11: =E10-D10 | F11: =F10-E10 | G11: =G10-F10 | H11: =H10-G10
A12: EBIT | B12: =B6-B8 | C12: =C6-C8 | D12: =D6-D8 | E12: =E6-E8 | F12: =F6-F8 | G12: =G6-G8 | H12: =H6-H8
A13: NOL carryforward, opening | B13: =Inputs!$B$26 | C13: =B17 | D13: =C17 | E13: =D17 | F13: =E17 | G13: =F17 | H13: =G17
A14: NOL used | B14: =IF(B12<=0,0,MIN(Inputs!$B$25*B12,B13)) | C14: =IF(C12<=0,0,MIN(Inputs!$B$25*C12,C13)) | D14: =IF(D12<=0,0,MIN(Inputs!$B$25*D12,D13)) | E14: =IF(E12<=0,0,MIN(Inputs!$B$25*E12,E13)) | F14: =IF(F12<=0,0,MIN(Inputs!$B$25*F12,F13)) | G14: =IF(G12<=0,0,MIN(Inputs!$B$25*G12,G13)) | H14: 0
A15: Taxable income | B15: =IF(B12<=0,0,B12-B14) | C15: =IF(C12<=0,0,C12-C14) | D15: =IF(D12<=0,0,D12-D14) | E15: =IF(E12<=0,0,E12-E14) | F15: =IF(F12<=0,0,F12-F14) | G15: =IF(G12<=0,0,G12-G14) | H15: =H12
A16: Cash taxes | B16: =Inputs!$B$21*B15 | C16: =Inputs!$C$21*C15 | D16: =Inputs!$D$21*D15 | E16: =Inputs!$E$21*E15 | F16: =Inputs!$F$21*F15 | G16: =Inputs!$G$21*G15 | H16: =Inputs!$G$21*H15
A17: NOL carryforward, closing | B17: =IF(B12<=0,B13-B12,B13-B14) | C17: =IF(C12<=0,C13-C12,C13-C14) | D17: =IF(D12<=0,D13-D12,D13-D14) | E17: =IF(E12<=0,E13-E12,E13-E14) | F17: =IF(F12<=0,F13-F12,F13-F14) | G17: =IF(G12<=0,G13-G12,G13-G14) | H17: =H13
A18: Effective tax rate | B18: =IF(B12=0,0,B16/B12) | C18: =IF(C12=0,0,C16/C12) | D18: =IF(D12=0,0,D16/D12) | E18: =IF(E12=0,0,E16/E12) | F18: =IF(F12=0,0,F16/F12) | G18: =IF(G12=0,0,G16/G12) | H18: =IF(H12=0,0,H16/H12)
A19: Free cash flow | B19: =B6-B16-B9-B11 | C19: =C6-C16-C9-C11 | D19: =D6-D16-D9-D11 | E19: =E6-E16-E9-E11 | F19: =F6-F16-F9-F11 | G19: =G6-G16-G9-G11 | H19: =H6-H16-H9-H11
A20: Discount factor | B20: =1/(1+Inputs!$B$24)^1 | C20: =1/(1+Inputs!$B$24)^2 | D20: =1/(1+Inputs!$B$24)^3 | E20: =1/(1+Inputs!$B$24)^4 | F20: =1/(1+Inputs!$B$24)^5 | G20: =1/(1+Inputs!$B$24)^6 | H20: =1/(1+Inputs!$B$24)^7
A21: PV of free cash flow | B21: =B19*B20 | C21: =C19*C20 | D21: =D19*D20 | E21: =E19*E20 | F21: =F19*F20 | G21: =G19*G20 | H21: =H19*H20

Sheet Bridge
A1: From enterprise value to the shareholders
A3: PV of free cash flow, years 1 to 6 | B3: =SUM(Model!B21:Model!G21)
A4: Terminal value at the end of year 6 | B4: =Model!H19/(Inputs!$B$24-Inputs!$G$6)
A5: PV of the terminal value | B5: =B4/(1+Inputs!$B$24)^6
A6: Enterprise value of operations | B6: =B3+B5
A7: PV of remaining NOL carryforward | B7: ='NOL schedule'!F206
A8: Plus cash | B8: =+Inputs!$B$33
A9: Plus rental investment property | B9: =+Inputs!$B$34
A10: Less revolving credit facility | B10: =-Inputs!$B$35
A11: Less long term debt | B11: =-Inputs!$B$36
A12: Less bank overdraft | B12: =-Inputs!$B$37
A13: Less unfunded pension | B13: =-Inputs!$B$38
A14: Equity value | B14: =B6+B7+SUM(B8:B13)
A15: Diluted shares | B15: =Inputs!$B$27
A16: Value per share | B16: =IF(Inputs!$B$27=0,"",B14/Inputs!$B$27)

Sheet Sensitivity
A1: Sensitivity — value per share
A2: A snapshot, not a formula: every cell is a full re-run of the model at different assumptions, which Excel cannot do from a formula. Change an Input and rebuild to refresh this sheet.
A5: WACC \ terminal growth | B5: 0.025 | C5: 0.03 | D5: 0.035 | E5: 0.04 | F5: 0.045
A6: 0.06 | B6: 172.58515 | C6: 193.99922 | D6: 223.9789 | E6: 268.94843 | F6: 343.89765
A7: 0.07 | B7: 131.84057 | C7: 143.03625 | D7: 157.43071 | E7: 176.62331 | F7: 203.49296
A8: 0.08 | B8: 105.9187 | C8: 112.45705 | D8: 120.44837 | E8: 130.43752 | F8: 143.28071
A9: 0.09 | B9: 87.978315 | C9: 92.070156 | D9: 96.905968 | E9: 102.70894 | F9: 109.80147
A10: 0.1 | B10: 74.82683 | C10: 77.507773 | D10: 80.60117 | E10: 84.210132 | F10: 88.475269

Sheet Drivers
A1: Drivers — what actually moves the answer
A2: How much a change in each driver moves the equity value, given the baseline assumptions. Each driver is moved by the amount shown in EVERY forecast year at once -- the five explicit years and the perpetuity together, not the perpetuity alone. These are a local measure around the current baseline and will shift somewhat as the assumptions are refined. The percentages are the same for the equity value and for the value per share, since the share count does not move.
A3: A snapshot, not a formula: every cell is a full re-run of the model at different assumptions, which Excel cannot do from a formula. Change an Input and rebuild to refresh this sheet.
A5: Moved one notch each way, in every year at once
A6: Driver | B6: Notch | C6: Down | D6: Base | E6: Up | F6: Span
A7: sales growth | B7: 1pp | C7: 102.5405 | D7: 120.44837 | E7: 148.59681 | F7: 46.056309
A8: ebitda margin | B8: 1pp | C8: 102.51789 | D8: 120.44837 | E8: 138.37884 | F8: 35.860948
A9: sales to net ppe | B9: 5% of itself | C9: 116.94013 | D9: 120.44837 | E9: 123.62249 | F9: 6.6823587
A10: depreciation rate | B10: 1pp | C10: 123.36759 | D10: 120.44837 | E10: 117.52915 | F10: 5.8384405
A11: cash tax rate | B11: 1pp | C11: 122.57071 | D11: 120.44837 | E11: 118.32602 | F11: 4.2446862
A12: receivables | B12: 1pp | C12: 122.2678 | D12: 120.44837 | E12: 118.62894 | F12: 3.6388582
A13: inventories | B13: 1pp | C13: 122.2678 | D13: 120.44837 | E13: 118.62894 | F13: 3.6388582
A14: prepaid | B14: 1pp | C14: 122.2678 | D14: 120.44837 | E14: 118.62894 | F14: 3.6388582
A15: payables | B15: 1pp | C15: 118.62894 | D15: 120.44837 | E15: 122.2678 | F15: 3.6388582
A16: accrued payroll | B16: 1pp | C16: 118.62894 | D16: 120.44837 | E16: 122.2678 | F16: 3.6388582
A17: other accrued | B17: 1pp | C17: 118.62894 | D17: 120.44837 | E17: 122.2678 | F17: 3.6388582
A18: workers comp | B18: 1pp | C18: 118.62894 | D18: 120.44837 | E18: 122.2678 | F18: 3.6388582
A21: One-way tables, two notches each way
A22: The notch is applied to every forecast year. The level row shows where the terminal ends up; the explicit years move by the same amount.
A24: sales growth | B24: -2 | C24: -1 | D24: base | E24: +1 | F24: +2
A25: terminal level (explicit years move too) | B25: 0.015 | C25: 0.025 | D25: 0.035 | E25: 0.045 | F25: 0.055
A26: value per share | B26: 90.146521 | C26: 102.5405 | D26: 120.44837 | E26: 148.59681 | F26: 199.27529
A28: ebitda margin | B28: -2 | C28: -1 | D28: base | E28: +1 | F28: +2
A29: terminal level (explicit years move too) | B29: 0.088 | C29: 0.098 | D29: 0.108 | E29: 0.118 | F29: 0.128
A30: value per share | B30: 84.58742 | C30: 102.51789 | D30: 120.44837 | E30: 138.37884 | F30: 156.30932
A32: sales to net ppe | B32: -10 | C32: -5 | D32: base | E32: +5 | F32: +10
A33: terminal level (explicit years move too) | B33: 5.67 | C33: 5.985 | D33: 6.3 | E33: 6.615 | F33: 6.93
A34: value per share | B34: 113.04209 | C34: 116.94013 | D34: 120.44837 | E34: 123.62249 | F34: 126.50805
A36: depreciation rate | B36: -2 | C36: -1 | D36: base | E36: +1 | F36: +2
A37: terminal level (explicit years move too) | B37: 0.11 | C37: 0.12 | D37: 0.13 | E37: 0.14 | F37: 0.15
A38: value per share | B38: 126.28681 | C38: 123.36759 | D38: 120.44837 | E38: 117.52915 | F38: 114.60993
A40: cash tax rate | B40: -2 | C40: -1 | D40: base | E40: +1 | F40: +2
A41: terminal level (explicit years move too) | B41: 0.25 | C41: 0.26 | D41: 0.27 | E41: 0.28 | F41: 0.29
A42: value per share | B42: 124.69305 | C42: 122.57071 | D42: 120.44837 | E42: 118.32602 | F42: 116.20368
A44: receivables | B44: -2 | C44: -1 | D44: base | E44: +1 | F44: +2
A45: terminal level (explicit years move too) | B45: 0.05 | C45: 0.06 | D45: 0.07 | E45: 0.08 | F45: 0.09
A46: value per share | B46: 124.08723 | C46: 122.2678 | D46: 120.44837 | E46: 118.62894 | F46: 116.80951
A48: inventories | B48: -2 | C48: -1 | D48: base | E48: +1 | F48: +2
A49: terminal level (explicit years move too) | B49: 0.175 | C49: 0.185 | D49: 0.195 | E49: 0.205 | F49: 0.215
A50: value per share | B50: 124.08723 | C50: 122.2678 | D50: 120.44837 | E50: 118.62894 | F50: 116.80951
...

Sheet Historical
A1: Historical driver ratios
A3: Ratio | B3: 2021 | C3: 2022 | D3: 2023 | E3: 2024 | F3: 2025 | G3: 2026
A4: sales_growth | C4: 0.11343977 | D4: 0.045841058 | E4: 0.067118075 | F4: 0.037929926 | G4: 0.061799275
A5: ebitda_margin | B5: 0.12054533 | C5: 0.11060418 | D5: 0.11077178 | E5: 0.10289628 | F5: 0.10082764 | G5: 0.099854296
A6: sales_to_net_ppe | B6: 8.1645085 | C6: 8.5384136 | D6: 8.8312044 | E6: 7.3222323 | F6: 7.1188624
A7: depreciation_rate | C7: 0.15618914 | D7: 0.17520349 | E7: 0.20349015 | F7: 0.17808844 | G7: 0.17074278
A8: cash_tax_rate | B8: 0.27521016 | C8: 0.26045339 | D8: 0.27448155 | E8: 0.27789384 | F8: 0.27144417
A9: realized_capex | C9: 18291 | D9: 24229 | E9: 55001 | F9: 40862 | G9: 106751
A10: operating_assets: receivables | B10: 0.077268947 | C10: 0.072824909 | D10: 0.072756846 | E10: 0.079641314 | F10: 0.069231228 | G10: 0.071712117
A11: operating_assets: inventories | B11: 0.17239499 | C11: 0.21431306 | D11: 0.17299032 | E11: 0.18425772 | F11: 0.22993987 | G11: 0.20909386
A12: operating_assets: prepaid | B12: 0.0099804073 | C12: 0.0086654224 | D12: 0.0068141396 | E12: 0.01132189 | F12: 0.013170515 | G12: 0.015334196
A13: operating_liabilities: payables | B13: 0.056915579 | C13: 0.049923211 | D13: 0.042693406 | E13: 0.050090787 | F13: 0.054621105 | G13: 0.061614071
A14: operating_liabilities: accrued_payroll | B14: 0.028083291 | C14: 0.019760051 | D14: 0.02758066 | E14: 0.033372298 | F14: 0.016659351 | G14: 0.029472481
A15: operating_liabilities: other_accrued | B15: 0.015857059 | C15: 0.012922286 | D15: 0.014483548 | E15: 0.014249383 | F15: 0.016529299 | G15: 0.017811926
A16: operating_liabilities: workers_comp | C16: 0.0079111342 | D16: 0.0073232995 | E16: 0.0071926531 | F16: 0.0095760111 | G16: 0.0090637448

Sheet NOL schedule
A1: Tax shield on the carryforward surviving year 6
A2: Year 7 onward is taxed at the full rate in the perpetuity, so the shield is valued here instead and added to the bridge.
A4: Year | B4: EBIT | C4: Opening balance | D4: Used | E4: Tax saved | F4: PV of tax saved | G4: Closing balance
A5: 7 | B5: =Model!H12 | C5: =Model!G17 | D5: =MIN(Inputs!$B$25*B5,C5) | E5: =IF(B5<=0,0,Inputs!$G$21*D5) | F5: =E5/(1+Inputs!$B$24)^A5 | G5: =IF(B5<=0,C5,C5-D5)
A6: 8 | B6: =B5*(1+Inputs!$G$6) | C6: =G5 | D6: =MIN(Inputs!$B$25*B6,C6) | E6: =IF(B6<=0,0,Inputs!$G$21*D6) | F6: =E6/(1+Inputs!$B$24)^A6 | G6: =IF(B6<=0,C6,C6-D6)
A7: 9 | B7: =B6*(1+Inputs!$G$6) | C7: =G6 | D7: =MIN(Inputs!$B$25*B7,C7) | E7: =IF(B7<=0,0,Inputs!$G$21*D7) | F7: =E7/(1+Inputs!$B$24)^A7 | G7: =IF(B7<=0,C7,C7-D7)
A8: 10 | B8: =B7*(1+Inputs!$G$6) | C8: =G7 | D8: =MIN(Inputs!$B$25*B8,C8) | E8: =IF(B8<=0,0,Inputs!$G$21*D8) | F8: =E8/(1+Inputs!$B$24)^A8 | G8: =IF(B8<=0,C8,C8-D8)
A9: 11 | B9: =B8*(1+Inputs!$G$6) | C9: =G8 | D9: =MIN(Inputs!$B$25*B9,C9) | E9: =IF(B9<=0,0,Inputs!$G$21*D9) | F9: =E9/(1+Inputs!$B$24)^A9 | G9: =IF(B9<=0,C9,C9-D9)
A10: 12 | B10: =B9*(1+Inputs!$G$6) | C10: =G9 | D10: =MIN(Inputs!$B$25*B10,C10) | E10: =IF(B10<=0,0,Inputs!$G$21*D10) | F10: =E10/(1+Inputs!$B$24)^A10 | G10: =IF(B10<=0,C10,C10-D10)
A11: 13 | B11: =B10*(1+Inputs!$G$6) | C11: =G10 | D11: =MIN(Inputs!$B$25*B11,C11) | E11: =IF(B11<=0,0,Inputs!$G$21*D11) | F11: =E11/(1+Inputs!$B$24)^A11 | G11: =IF(B11<=0,C11,C11-D11)
A12: 14 | B12: =B11*(1+Inputs!$G$6) | C12: =G11 | D12: =MIN(Inputs!$B$25*B12,C12) | E12: =IF(B12<=0,0,Inputs!$G$21*D12) | F12: =E12/(1+Inputs!$B$24)^A12 | G12: =IF(B12<=0,C12,C12-D12)
A13: 15 | B13: =B12*(1+Inputs!$G$6) | C13: =G12 | D13: =MIN(Inputs!$B$25*B13,C13) | E13: =IF(B13<=0,0,Inputs!$G$21*D13) | F13: =E13/(1+Inputs!$B$24)^A13 | G13: =IF(B13<=0,C13,C13-D13)
A14: 16 | B14: =B13*(1+Inputs!$G$6) | C14: =G13 | D14: =MIN(Inputs!$B$25*B14,C14) | E14: =IF(B14<=0,0,Inputs!$G$21*D14) | F14: =E14/(1+Inputs!$B$24)^A14 | G14: =IF(B14<=0,C14,C14-D14)
A15: 17 | B15: =B14*(1+Inputs!$G$6) | C15: =G14 | D15: =MIN(Inputs!$B$25*B15,C15) | E15: =IF(B15<=0,0,Inputs!$G$21*D15) | F15: =E15/(1+Inputs!$B$24)^A15 | G15: =IF(B15<=0,C15,C15-D15)
A16: 18 | B16: =B15*(1+Inputs!$G$6) | C16: =G15 | D16: =MIN(Inputs!$B$25*B16,C16) | E16: =IF(B16<=0,0,Inputs!$G$21*D16) | F16: =E16/(1+Inputs!$B$24)^A16 | G16: =IF(B16<=0,C16,C16-D16)
A17: 19 | B17: =B16*(1+Inputs!$G$6) | C17: =G16 | D17: =MIN(Inputs!$B$25*B17,C17) | E17: =IF(B17<=0,0,Inputs!$G$21*D17) | F17: =E17/(1+Inputs!$B$24)^A17 | G17: =IF(B17<=0,C17,C17-D17)
... A204: 206 | B204: =B203*(1+Inputs!$G$6) | C204: =G203 | D204: =MIN(Inputs!$B$25*B204,C204) | E204: =IF(B204<=0,0,Inputs!$G$21*D204) | F204: =E204/(1+Inputs!$B$24)^A204 | G204: =IF(B204<=0,C204,C204-D204)
A206: PV of the shield | F206: =SUM(F5:F204)

Sheet Check
A1: Does this workbook still agree with the engine that wrote it?
A2: Every cell below compares a formula on the Model or Bridge sheet against the number dcf_engine.py computed when this file was written. Anything but 'ok' means the workbook has been edited in a way that changed the arithmetic, not just the assumptions. Tolerance 1e-06.
A4: Overall | B4: =IF(COUNTIF(B7:H29,"FAIL")>0,"FAIL","ok")
A6: Model line | B6: Year 1 | C6: Year 2 | D6: Year 3 | E6: Year 4 | F6: Year 5 | G6: Year 6 | H6: Year 7
A7: sales | B7: =IF(ABS(Model!B4-(1228578.285))>1e-06,"FAIL","ok") | C7: =IF(ABS(Model!C4-(1308435.873525))>1e-06,"FAIL","ok") | D7: =IF(ABS(Model!D4-(1386942.0259365))>1e-06,"FAIL","ok") | E7: =IF(ABS(Model!E4-(1449354.4171036424))>1e-06,"FAIL","ok") | F7: =IF(ABS(Model!F4-(1500081.8217022698))>1e-06,"FAIL","ok") | G7: =IF(ABS(Model!G4-(1552584.6854618492))>1e-06,"FAIL","ok") | H7: =IF(ABS(Model!H4-(1606925.149453014))>1e-06,"FAIL","ok")
A8: ebitda | B8: =IF(ABS(Model!B6-(125314.98506999998))>1e-06,"FAIL","ok") | C8: =IF(ABS(Model!C6-(138694.20259365))>1e-06,"FAIL","ok") | D8: =IF(ABS(Model!D6-(149789.738801142))>1e-06,"FAIL","ok") | E8: =IF(ABS(Model!E6-(156530.2770471934))>1e-06,"FAIL","ok") | F8: =IF(ABS(Model!F6-(162008.83674384517))>1e-06,"FAIL","ok") | G8: =IF(ABS(Model!G6-(167679.14602987975))>1e-06,"FAIL","ok") | H8: =IF(ABS(Model!H6-(173547.91614092552))>1e-06,"FAIL","ok")
A9: net_ppe | B9: =IF(ABS(Model!B7-(249225.88067142857))>1e-06,"FAIL","ok") | C9: =IF(ABS(Model!C7-(247668.21891723215))>1e-06,"FAIL","ok") | D9: =IF(ABS(Model!D7-(245653.29103451563))>1e-06,"FAIL","ok") | E9: =IF(ABS(Model!E7-(243915.7433662227))>1e-06,"FAIL","ok") | F9: =IF(ABS(Model!F7-(246442.0135653729))>1e-06,"FAIL","ok") | G9: =IF(ABS(Model!G7-(255067.48404016095))>1e-06,"FAIL","ok") | H9: =IF(ABS(Model!H7-(263994.8459815666))>1e-06,"FAIL","ok")
A10: depreciation | B10: =IF(ABS(Model!B8-(34118.280000000006))>1e-06,"FAIL","ok") | C10: =IF(ABS(Model!C8-(33645.49389064286))>1e-06,"FAIL","ok") | D10: =IF(ABS(Model!D8-(32196.86845924018))>1e-06,"FAIL","ok") | E10: =IF(ABS(Model!E8-(31934.927834487033))>1e-06,"FAIL","ok") | F10: =IF(ABS(Model!F8-(31709.046637608953))>1e-06,"FAIL","ok") | G10: =IF(ABS(Model!G8-(32037.46176349848))>1e-06,"FAIL","ok") | H10: =IF(ABS(Model!H8-(33158.772925220925))>1e-06,"FAIL","ok")
A11: capex | B11: =IF(ABS(Model!B9-(39642.16067142858))>1e-06,"FAIL","ok") | C11: =IF(ABS(Model!C9-(32087.832136446435))>1e-06,"FAIL","ok") | D11: =IF(ABS(Model!D9-(30181.940576523655))>1e-06,"FAIL","ok") | E11: =IF(ABS(Model!E9-(30197.380166194118))>1e-06,"FAIL","ok") | F11: =IF(ABS(Model!F9-(34235.31683675915))>1e-06,"FAIL","ok") | G11: =IF(ABS(Model!G9-(40662.93223828652))>1e-06,"FAIL","ok") | H11: =IF(ABS(Model!H9-(42086.134866626555))>1e-06,"FAIL","ok")
A12: nwc | B12: =IF(ABS(Model!B10-(218686.93472999998))>1e-06,"FAIL","ok") | C12: =IF(ABS(Model!C10-(230284.71374039998))>1e-06,"FAIL","ok") | D12: =IF(ABS(Model!D10-(241327.91251295104))>1e-06,"FAIL","ok") | E12: =IF(ABS(Model!E10-(249288.95974182646))>1e-06,"FAIL","ok") | F12: =IF(ABS(Model!F10-(256513.99151108816))>1e-06,"FAIL","ok") | G12: =IF(ABS(Model!G10-(265491.9812139762))>1e-06,"FAIL","ok") | H12: =IF(ABS(Model!H10-(274784.2005564654))>1e-06,"FAIL","ok")
A13: delta_nwc | B13: =IF(ABS(Model!B11-(9207.934729999979))>1e-06,"FAIL","ok") | C13: =IF(ABS(Model!C11-(11597.779010400001))>1e-06,"FAIL","ok") | D13: =IF(ABS(Model!D11-(11043.198772551055))>1e-06,"FAIL","ok") | E13: =IF(ABS(Model!E11-(7961.0472288754245))>1e-06,"FAIL","ok") | F13: =IF(ABS(Model!F11-(7225.031769261695))>1e-06,"FAIL","ok") | G13: =IF(ABS(Model!G11-(8977.989702888066))>1e-06,"FAIL","ok") | H13: =IF(ABS(Model!H11-(9292.219342489203))>1e-06,"FAIL","ok")
A14: ebit | B14: =IF(ABS(Model!B12-(91196.70506999997))>1e-06,"FAIL","ok") | C14: =IF(ABS(Model!C12-(105048.70870300714))>1e-06,"FAIL","ok") | D14: =IF(ABS(Model!D12-(117592.87034190181))>1e-06,"FAIL","ok") | E14: =IF(ABS(Model!E12-(124595.34921270638))>1e-06,"FAIL","ok") | F14: =IF(ABS(Model!F12-(130299.7901062362))>1e-06,"FAIL","ok") | G14: =IF(ABS(Model!G12-(135641.68426638126))>1e-06,"FAIL","ok") | H14: =IF(ABS(Model!H12-(140389.1432157046))>1e-06,"FAIL","ok")
A15: nol_used | B15: =IF(ABS(Model!B14-(0.0))>1e-06,"FAIL","ok") | C15: =IF(ABS(Model!C14-(0.0))>1e-06,"FAIL","ok") | D15: =IF(ABS(Model!D14-(0.0))>1e-06,"FAIL","ok") | E15: =IF(ABS(Model!E14-(0.0))>1e-06,"FAIL","ok") | F15: =IF(ABS(Model!F14-(0.0))>1e-06,"FAIL","ok") | G15: =IF(ABS(Model!G14-(0.0))>1e-06,"FAIL","ok") | H15: =IF(ABS(Model!H14-(0.0))>1e-06,"FAIL","ok")
A16: taxable_income | B16: =IF(ABS(Model!B15-(91196.70506999997))>1e-06,"FAIL","ok") | C16: =IF(ABS(Model!C15-(105048.70870300714))>1e-06,"FAIL","ok") | D16: =IF(ABS(Model!D15-(117592.87034190181))>1e-06,"FAIL","ok") | E16: =IF(ABS(Model!E15-(124595.34921270638))>1e-06,"FAIL","ok") | F16: =IF(ABS(Model!F15-(130299.7901062362))>1e-06,"FAIL","ok") | G16: =IF(ABS(Model!G15-(135641.68426638126))>1e-06,"FAIL","ok") | H16: =IF(ABS(Model!H15-(140389.1432157046))>1e-06,"FAIL","ok")
A17: tax | B17: =IF(ABS(Model!B16-(24623.110368899994))>1e-06,"FAIL","ok") | C17: =IF(ABS(Model!C16-(28363.15134981193))>1e-06,"FAIL","ok") | D17: =IF(ABS(Model!D16-(31750.07499231349))>1e-06,"FAIL","ok") | E17: =IF(ABS(Model!E16-(33640.74428743072))>1e-06,"FAIL","ok") | F17: =IF(ABS(Model!F16-(35180.94332868378))>1e-06,"FAIL","ok") | G17: =IF(ABS(Model!G16-(36623.25475192294))>1e-06,"FAIL","ok") | H17: =IF(ABS(Model!H16-(37905.068668240245))>1e-06,"FAIL","ok")
A18: nol_close | B18: =IF(ABS(Model!B17-(0.0))>1e-06,"FAIL","ok") | C18: =IF(ABS(Model!C17-(0.0))>1e-06,"FAIL","ok") | D18: =IF(ABS(Model!D17-(0.0))>1e-06,"FAIL","ok") | E18: =IF(ABS(Model!E17-(0.0))>1e-06,"FAIL","ok") | F18: =IF(ABS(Model!F17-(0.0))>1e-06,"FAIL","ok") | G18: =IF(ABS(Model!G17-(0.0))>1e-06,"FAIL","ok") | H18: =IF(ABS(Model!H17-(0.0))>1e-06,"FAIL","ok")
A19: fcf | B19: =IF(ABS(Model!B19-(51841.779299671434))>1e-06,"FAIL","ok") | C19: =IF(ABS(Model!C19-(66645.44009699163))>1e-06,"FAIL","ok") | D19: =IF(ABS(Model!D19-(76814.5244597538))>1e-06,"FAIL","ok") | E19: =IF(ABS(Model!E19-(84731.10536469315))>1e-06,"FAIL","ok") | F19: =IF(ABS(Model!F19-(85367.54480914053))>1e-06,"FAIL","ok") | G19: =IF(ABS(Model!G19-(81414.96933678222))>1e-06,"FAIL","ok") | H19: =IF(ABS(Model!H19-(84264.49326356951))>1e-06,"FAIL","ok")
A20: pv_fcf | B20: =IF(ABS(Model!B21-(48001.64749969577))>1e-06,"FAIL","ok") | C20: =IF(ABS(Model!C21-(57137.72299124797))>1e-06,"FAIL","ok") | D20: =IF(ABS(Model!D21-(60977.84609478499))>1e-06,"FAIL","ok") | E20: =IF(ABS(Model!E21-(62279.89190349118))>1e-06,"FAIL","ok") | F20: =IF(ABS(Model!F21-(58099.71656912702))>1e-06,"FAIL","ok") | G20: =IF(ABS(Model!G21-(51305.24084965944))>1e-06,"FAIL","ok") | H20: =IF(ABS(Model!H21-(49167.52248092358))>1e-06,"FAIL","ok")
A22: Bridge figure | B22: Check
A23: ev_ops | B23: =IF(ABS(Bridge!B6-(1517822.6054501727))>1e-06,"FAIL","ok")
A24: pv_nol | B24: =IF(ABS(Bridge!B7-(0.0))>1e-06,"FAIL","ok")
A25: equity_value | B25: =IF(ABS(Bridge!B14-(1418568.6054501727))>1e-06,"FAIL","ok")
A26: terminal_value | B26: =IF(ABS(Bridge!B4-(1872544.2947459894))>1e-06,"FAIL","ok")
A27: pv_terminal | B27: =IF(ABS(Bridge!B5-(1180020.5395421663))>1e-06,"FAIL","ok")
A28: pv_explicit | B28: =IF(ABS(Bridge!B3-(337802.0659080064))>1e-06,"FAIL","ok")
A29: sensitivity grid centre = base case | B29: =IF(ABS(Sensitivity!D8-(120.44836767454385))>1e-06,"FAIL","ok")
